Workbook
Name UPDATE: 'Data Sheet'!$E$1

Sheet Profit & Loss
A1: ='Data Sheet'!B1 -> INFOSYS LTD | H1: =UPDATE | M1: SCREENER.IN
A3: Narration | B3: ='Data Sheet'!B16 -> 42825 | C3: ='Data Sheet'!C16 -> 43190 | D3: ='Data Sheet'!D16 -> 43555 | E3: ='Data Sheet'!E16 -> 43921 | F3: ='Data Sheet'!F16 -> 44286 | G3: ='Data Sheet'!G16 -> 44651 | H3: ='Data Sheet'!H16 -> 45016 | I3: ='Data Sheet'!I16 -> 45382 | ... K3: ='Data Sheet'!K16 -> 46112 | L3: Trailing | M3: Best Case | N3: Worst Case
A4: Sales | B4: ='Data Sheet'!B17 -> 68484 | C4: ='Data Sheet'!C17 -> 70522 | D4: ='Data Sheet'!D17 -> 82675 | E4: ='Data Sheet'!E17 -> 90791 | F4: ='Data Sheet'!F17 -> 100472 | G4: ='Data Sheet'!G17 -> 121641 | H4: ='Data Sheet'!H17 -> 146767 | I4: ='Data Sheet'!I17 -> 153670 | ... K4: ='Data Sheet'!K17 -> 178650 | L4: =SUM(Quarters!H4:K4) -> 184582 | M4: =$K4+M23*K4 -> 195814.61 | N4: =$K4+N23*L4 -> 191150.27
A5: Expenses | B5: =SUM('Data Sheet'!B18,'Data Sheet'!B20:B24, -1*'Data Sheet'!B19) -> 49880 | C5: =SUM('Data Sheet'!C18,'Data Sheet'!C20:C24, -1*'Data Sheet'!C19) -> 51700 | D5: =SUM('Data Sheet'!D18,'Data Sheet'!D20:D24, -1*'Data Sheet'!D19) -> 62505 | E5: =SUM('Data Sheet'!E18,'Data Sheet'!E20:E24, -1*'Data Sheet'!E19) -> 68524 | F5: =SUM('Data Sheet'!F18,'Data Sheet'!F20:F24, -1*'Data Sheet'!F19) -> 72583 | G5: =SUM('Data Sheet'!G18,'Data Sheet'!G20:G24, -1*'Data Sheet'!G19) -> 90150 | H5: =SUM('Data Sheet'!H18,'Data Sheet'!H20:H24, -1*'Data Sheet'!H19) -> 111637 | I5: =SUM('Data Sheet'!I18,'Data Sheet'!I20:I24, -1*'Data Sheet'!I19) -> 117245 | ... K5: =SUM('Data Sheet'!K18,'Data Sheet'!K20:K24, -1*'Data Sheet'!K19) -> 136370 | L5: =SUM(Quarters!H5:K5) -> 140837 | M5: =M4-M6 -> 149188.11 | N5: =N4-N6 -> 145848.62
A6: Operating Profit | B6: =B4-B5 -> 18604 | C6: =C4-C5 -> 18822 | D6: =D4-D5 -> 20170 | E6: =E4-E5 -> 22267 | F6: =F4-F5 -> 27889 | G6: =G4-G5 -> 31491 | H6: =H4-H5 -> 35130 | I6: =I4-I5 -> 36425 | ... K6: =K4-K5 -> 42280 | L6: =SUM(Quarters!H6:K6) -> 43745 | M6: =M4*M24 -> 46626.497 | N6: =N4*N24 -> 45301.646
A7: Other Income | B7: ='Data Sheet'!B25 -> 3050 | C7: ='Data Sheet'!C25 -> 3311 | D7: ='Data Sheet'!D25 -> 2882 | E7: ='Data Sheet'!E25 -> 2803 | F7: ='Data Sheet'!F25 -> 2201 | G7: ='Data Sheet'!G25 -> 2295 | H7: ='Data Sheet'!H25 -> 2701 | I7: ='Data Sheet'!I25 -> 4711 | ... K7: ='Data Sheet'!K25 -> 3033 | L7: =SUM(Quarters!H7:K7) -> 2975 | M7: 0 | N7: 0
A8: Depreciation | B8: ='Data Sheet'!B26 -> 1703 | C8: ='Data Sheet'!C26 -> 1863 | D8: ='Data Sheet'!D26 -> 2011 | E8: ='Data Sheet'!E26 -> 2893 | F8: ='Data Sheet'!F26 -> 3267 | G8: ='Data Sheet'!G26 -> 3476 | H8: ='Data Sheet'!H26 -> 4225 | I8: ='Data Sheet'!I26 -> 4678 | ... K8: ='Data Sheet'!K26 -> 4902 | L8: =SUM(Quarters!H8:K8) -> 5007 | M8: =+$L8 -> 5007 | N8: =+$L8 -> 5007
A9: Interest | B9: ='Data Sheet'!B27 -> 0 | C9: ='Data Sheet'!C27 -> 0 | D9: ='Data Sheet'!D27 -> 0 | E9: ='Data Sheet'!E27 -> 170 | F9: ='Data Sheet'!F27 -> 195 | G9: ='Data Sheet'!G27 -> 200 | H9: ='Data Sheet'!H27 -> 284 | I9: ='Data Sheet'!I27 -> 470 | ... K9: ='Data Sheet'!K27 -> 416 | L9: =SUM(Quarters!H9:K9) -> 430 | M9: =+$L9 -> 430 | N9: =+$L9 -> 430
A10: Profit before tax | B10: ='Data Sheet'!B28 -> 19951 | C10: ='Data Sheet'!C28 -> 20270 | D10: ='Data Sheet'!D28 -> 21041 | E10: ='Data Sheet'!E28 -> 22007 | F10: ='Data Sheet'!F28 -> 26628 | G10: ='Data Sheet'!G28 -> 30110 | H10: ='Data Sheet'!H28 -> 33322 | I10: ='Data Sheet'!I28 -> 35988 | ... K10: ='Data Sheet'!K28 -> 39995 | L10: =SUM(Quarters!H10:K10) -> 41283 | M10: =M6+M7-SUM(M8:M9) -> 41189.497 | N10: =N6+N7-SUM(N8:N9) -> 39864.646
A11: Tax | B11: ='Data Sheet'!B29 -> 5598 | C11: ='Data Sheet'!C29 -> 4241 | D11: ='Data Sheet'!D29 -> 5631 | E11: ='Data Sheet'!E29 -> 5368 | F11: ='Data Sheet'!F29 -> 7205 | G11: ='Data Sheet'!G29 -> 7964 | H11: ='Data Sheet'!H29 -> 9214 | I11: ='Data Sheet'!I29 -> 9740 | ... K11: ='Data Sheet'!K29 -> 10521 | L11: =SUM(Quarters!H11:K11) -> 10958 | M11: =IF($L10>0,$L11/$L10,0) -> 0.26543614 | N11: =IF($L10>0,$L11/$L10,0) -> 0.26543614
A12: Net profit | B12: ='Data Sheet'!B30 -> 14353 | C12: ='Data Sheet'!C30 -> 16029 | D12: ='Data Sheet'!D30 -> 15404 | E12: ='Data Sheet'!E30 -> 16594 | F12: ='Data Sheet'!F30 -> 19351 | G12: ='Data Sheet'!G30 -> 22110 | H12: ='Data Sheet'!H30 -> 24095 | I12: ='Data Sheet'!I30 -> 26233 | ... K12: ='Data Sheet'!K30 -> 29440 | L12: =SUM(Quarters!H12:K12) -> 30288 | M12: =M10-M11*M10 -> 30256.316 | N12: =N10-N11*N10 -> 29283.128
A13: EPS | B13: =IF('Data Sheet'!B93>0,B12/'Data Sheet'!B93,0) -> 31.243606 | C13: =IF('Data Sheet'!C93>0,C12/'Data Sheet'!C93,0) -> 36.694748 | D13: =IF('Data Sheet'!D93>0,D12/'Data Sheet'!D93,0) -> 35.258303 | E13: =IF('Data Sheet'!E93>0,E12/'Data Sheet'!E93,0) -> 38.962198 | F13: =IF('Data Sheet'!F93>0,F12/'Data Sheet'!F93,0) -> 45.41742 | G13: =IF('Data Sheet'!G93>0,G12/'Data Sheet'!G93,0) -> 52.559013 | H13: =IF('Data Sheet'!H93>0,H12/'Data Sheet'!H93,0) -> 58.079834 | I13: =IF('Data Sheet'!I93>0,I12/'Data Sheet'!I93,0) -> 63.198343 | ... K13: =IF('Data Sheet'!K93>0,K12/'Data Sheet'!K93,0) -> 72.590985 | L13: =IF('Data Sheet'!$B6>0,'Profit & Loss'!L12/'Data Sheet'!$B6,0) -> 74.633478 | M13: =IF('Data Sheet'!$B6>0,'Profit & Loss'!M12/'Data Sheet'!$B6,0) -> 74.555405 | N13: =IF('Data Sheet'!$B6>0,'Profit & Loss'!N12/'Data Sheet'!$B6,0) -> 72.157346
A14: Price to earning | B14: =IF(B15>0,B15/B13,"") -> 16.359507 | C14: =IF(C15>0,C15/C13,"") -> 15.421825 | D14: =IF(D15>0,D15/D13,"") -> 21.097158 | E14: =IF(E15>0,E15/E13,"") -> 16.464677 | F14: =IF(F15>0,F15/F13,"") -> 30.121702 | G14: =IF(G15>0,G15/G13,"") -> 36.280171 | H14: =IF(H15>0,H15/H13,"") -> 24.585986 | I14: =IF(I15>0,I15/I13,"") -> 23.703944 | ... K14: =IF(K15>0,K15/K13,"") -> 17.228035 | L14: =IF(L13>0,L15/L13,0) -> 13.903948 | M14: =M25 -> 19.814044 | N14: =N25 -> 13.903948
A15: Price | B15: ='Data Sheet'!B90 -> 511.13 | C15: ='Data Sheet'!C90 -> 565.9 | D15: ='Data Sheet'!D90 -> 743.85 | E15: ='Data Sheet'!E90 -> 641.5 | F15: ='Data Sheet'!F90 -> 1368.05 | G15: ='Data Sheet'!G90 -> 1906.85 | H15: ='Data Sheet'!H90 -> 1427.95 | I15: ='Data Sheet'!I90 -> 1498.05 | ... K15: ='Data Sheet'!K90 -> 1250.6 | L15: ='Data Sheet'!B8 -> 1037.7 | M15: =M13*M14 -> 1477.244 | N15: =N13*N14 -> 1003.272
A17: RATIOS:
A18: Dividend Payout | B18: =IF('Data Sheet'!B30>0, 'Data Sheet'!B31/'Data Sheet'!B30, 0) -> 0.41047865 | C18: =IF('Data Sheet'!C30>0, 'Data Sheet'!C31/'Data Sheet'!C30, 0) -> 0.59052966 | D18: =IF('Data Sheet'!D30>0, 'Data Sheet'!D31/'Data Sheet'!D30, 0) -> 0.59870813 | E18: =IF('Data Sheet'!E30>0, 'Data Sheet'!E31/'Data Sheet'!E30, 0) -> 0.44757141 | F18: =IF('Data Sheet'!F30>0, 'Data Sheet'!F31/'Data Sheet'!F30, 0) -> 0.59271355 | G18: =IF('Data Sheet'!G30>0, 'Data Sheet'!G31/'Data Sheet'!G30, 0) -> 0.58831298 | H18: =IF('Data Sheet'!H30>0, 'Data Sheet'!H31/'Data Sheet'!H30, 0) -> 0.58390537 | I18: =IF('Data Sheet'!I30>0, 'Data Sheet'!I31/'Data Sheet'!I30, 0) -> 0.72630656 | ... K18: =IF('Data Sheet'!K30>0, 'Data Sheet'!K31/'Data Sheet'!K30, 0) -> 0.66
A19: OPM | B19: =IF(B6>0,B6/B4,0) -> 0.27165469 | C19: =IF(C6>0,C6/C4,0) -> 0.26689544 | D19: =IF(D6>0,D6/D4,0) -> 0.24396734 | E19: =IF(E6>0,E6/E4,0) -> 0.24525559 | F19: =IF(F6>0,F6/F4,0) -> 0.27757982 | G19: =IF(G6>0,G6/G4,0) -> 0.25888475 | H19: =IF(H6>0,H6/H4,0) -> 0.23935898 | I19: =IF(I6>0,I6/I4,0) -> 0.2370339 | ... L19: =IF(L6>0,L6/L4,0) -> 0.23699494
G22: TRENDS: | H22: 10 YEARS | I22: 7 YEARS | J22: 5 YEARS | K22: 3 YEARS | L22: RECENT | M22: BEST | N22: WORST
G23: Sales Growth | H23: =IF(B4=0,"",POWER($K4/B4,1/9)-1) -> 0.11241852 | I23: =IF(D4=0,"",POWER($K4/D4,1/7)-1) -> 0.11635961 | J23: =IF(F4=0,"",POWER($K4/F4,1/5)-1) -> 0.12199674 | K23: =IF(H4=0,"",POWER($K4/H4, 1/3)-1) -> 0.067722024 | L23: =IF(ISERROR(MAX(IF(J4=0,"",(K4-J4)/J4),IF(K4=0,"",(L4-K4)/K4))),"",MAX(IF(J4=0,"",(K4-J4)/J4),IF(K4=0,"",(L4-K4)/K4))) -> 0.096079514 | M23: =MAX(K23:L23) -> 0.096079514 | N23: =MIN(H23:L23) -> 0.067722024
G24: OPM | H24: =IF(SUM(B4:$K$4)=0,"",SUMPRODUCT(B19:$K$19,B4:$K$4)/SUM(B4:$K$4)) -> 0.24842648 | I24: =IF(SUM(E4:$K$4)=0,"",SUMPRODUCT(E19:$K$19,E4:$K$4)/SUM(E4:$K$4)) -> 0.2457829 | J24: =IF(SUM(G4:$K$4)=0,"",SUMPRODUCT(G19:$K$19,G4:$K$4)/SUM(G4:$K$4)) -> 0.2416625 | K24: =IF(SUM(I4:$K$4)=0, "", SUMPRODUCT(I19:$K$19,I4:$K$4)/SUM(I4:$K$4)) -> 0.23811552 | L24: =L19 -> 0.23699494 | M24: =MAX(K24:L24) -> 0.23811552 | N24: =MIN(H24:L24) -> 0.23699494
G25: Price to Earning | H25: =IF(ISERROR(AVERAGEIF(B14:$L14,">0")),"",AVERAGEIF(B14:$L14,">0")) -> 21.780655 | I25: =IF(ISERROR(AVERAGEIF(E14:$L14,">0")),"",AVERAGEIF(E14:$L14,">0")) -> 23.338589 | J25: =IF(ISERROR(AVERAGEIF(G14:$L14,">0")),"",AVERAGEIF(G14:$L14,">0")) -> 23.353722 | K25: =IF(ISERROR(AVERAGEIF(I14:$L14,">0")),"",AVERAGEIF(I14:$L14,">0")) -> 19.814044 | L25: =L14 -> 13.903948 | M25: =MAX(K25:L25) -> 19.814044 | N25: =MIN(H25:L25) -> 13.903948

Sheet Quarters
A1: ='Profit & Loss'!A1 -> INFOSYS LTD | E1: =UPDATE | J1: SCREENER.IN
A3: Narration | B3: ='Data Sheet'!B41 -> 45382 | C3: ='Data Sheet'!C41 -> 45473 | D3: ='Data Sheet'!D41 -> 45565 | E3: ='Data Sheet'!E41 -> 45657 | F3: ='Data Sheet'!F41 -> 45747 | G3: ='Data Sheet'!G41 -> 45838 | H3: ='Data Sheet'!H41 -> 45930 | I3: ='Data Sheet'!I41 -> 46022 | ... K3: ='Data Sheet'!K41 -> 46203
A4: Sales | B4: ='Data Sheet'!B42 -> 37923 | C4: ='Data Sheet'!C42 -> 39315 | D4: ='Data Sheet'!D42 -> 40986 | E4: ='Data Sheet'!E42 -> 41764 | F4: ='Data Sheet'!F42 -> 40925 | G4: ='Data Sheet'!G42 -> 42279 | H4: ='Data Sheet'!H42 -> 44490 | I4: ='Data Sheet'!I42 -> 45479 | ... K4: ='Data Sheet'!K42 -> 48211
A5: Expenses | B5: ='Data Sheet'!B43 -> 29139 | C5: ='Data Sheet'!C43 -> 29878 | D5: ='Data Sheet'!D43 -> 31177 | E5: ='Data Sheet'!E43 -> 31649 | F5: ='Data Sheet'!F43 -> 31051 | G5: ='Data Sheet'!G43 -> 32336 | H5: ='Data Sheet'!H43 -> 33955 | I5: ='Data Sheet'!I43 -> 34845 | ... K5: ='Data Sheet'!K43 -> 36802
A6: Operating Profit | B6: ='Data Sheet'!B50 -> 8784 | C6: ='Data Sheet'!C50 -> 9437 | D6: ='Data Sheet'!D50 -> 9809 | E6: ='Data Sheet'!E50 -> 10115 | F6: ='Data Sheet'!F50 -> 9874 | G6: ='Data Sheet'!G50 -> 9943 | H6: ='Data Sheet'!H50 -> 10535 | I6: ='Data Sheet'!I50 -> 10634 | ... K6: ='Data Sheet'!K50 -> 11409
A7: Other Income | B7: ='Data Sheet'!B44 -> 2729 | C7: ='Data Sheet'!C44 -> 838 | D7: ='Data Sheet'!D44 -> 712 | E7: ='Data Sheet'!E44 -> 859 | F7: ='Data Sheet'!F44 -> 1190 | G7: ='Data Sheet'!G44 -> 1042 | H7: ='Data Sheet'!H44 -> 982 | I7: ='Data Sheet'!I44 -> -150 | ... K7: ='Data Sheet'!K44 -> 984
A8: Depreciation | B8: ='Data Sheet'!B45 -> 1163 | C8: ='Data Sheet'!C45 -> 1149 | D8: ='Data Sheet'!D45 -> 1160 | E8: ='Data Sheet'!E45 -> 1203 | F8: ='Data Sheet'!F45 -> 1299 | G8: ='Data Sheet'!G45 -> 1140 | H8: ='Data Sheet'!H45 -> 1182 | I8: ='Data Sheet'!I45 -> 1155 | ... K8: ='Data Sheet'!K45 -> 1246
A9: Interest | B9: ='Data Sheet'!B46 -> 110 | C9: ='Data Sheet'!C46 -> 105 | D9: ='Data Sheet'!D46 -> 108 | E9: ='Data Sheet'!E46 -> 101 | F9: ='Data Sheet'!F46 -> 102 | G9: ='Data Sheet'!G46 -> 105 | H9: ='Data Sheet'!H46 -> 106 | I9: ='Data Sheet'!I46 -> 100 | ... K9: ='Data Sheet'!K46 -> 119
A10: Profit before tax | B10: ='Data Sheet'!B47 -> 10240 | C10: ='Data Sheet'!C47 -> 9021 | D10: ='Data Sheet'!D47 -> 9253 | E10: ='Data Sheet'!E47 -> 9670 | F10: ='Data Sheet'!F47 -> 9663 | G10: ='Data Sheet'!G47 -> 9740 | H10: ='Data Sheet'!H47 -> 10229 | I10: ='Data Sheet'!I47 -> 9229 | ... K10: ='Data Sheet'!K47 -> 11028
A11: Tax | B11: ='Data Sheet'!B48 -> 2265 | C11: ='Data Sheet'!C48 -> 2647 | D11: ='Data Sheet'!D48 -> 2737 | E11: ='Data Sheet'!E48 -> 2848 | F11: ='Data Sheet'!F48 -> 2625 | G11: ='Data Sheet'!G48 -> 2816 | H11: ='Data Sheet'!H48 -> 2854 | I11: ='Data Sheet'!I48 -> 2563 | ... K11: ='Data Sheet'!K48 -> 3253
A12: Net profit | B12: ='Data Sheet'!B49 -> 7969 | C12: ='Data Sheet'!C49 -> 6368 | D12: ='Data Sheet'!D49 -> 6506 | E12: ='Data Sheet'!E49 -> 6806 | F12: ='Data Sheet'!F49 -> 7033 | G12: ='Data Sheet'!G49 -> 6921 | H12: ='Data Sheet'!H49 -> 7364 | I12: ='Data Sheet'!I49 -> 6654 | ... K12: ='Data Sheet'!K49 -> 7769
A14: OPM | B14: =IF(B4>0,B6/B4,"") -> 0.23162724 | C14: =IF(C4>0,C6/C4,"") -> 0.24003561 | D14: =IF(D4>0,D6/D4,"") -> 0.23932562 | E14: =IF(E4>0,E6/E4,"") -> 0.24219423 | F14: =IF(F4>0,F6/F4,"") -> 0.24127062 | G14: =IF(G4>0,G6/G4,"") -> 0.23517586 | H14: =IF(H4>0,H6/H4,"") -> 0.23679479 | I14: =IF(I4>0,I6/I4,"") -> 0.2338222 | ... K14: =IF(K4>0,K6/K4,"") -> 0.23664724

Sheet Balance Sheet
A1: ='Profit & Loss'!A1 -> INFOSYS LTD | E1: =UPDATE | J1: SCREENER.IN
A3: Narration | B3: ='Data Sheet'!B56 -> 42825 | C3: ='Data Sheet'!C56 -> 43190 | D3: ='Data Sheet'!D56 -> 43555 | E3: ='Data Sheet'!E56 -> 43921 | F3: ='Data Sheet'!F56 -> 44286 | G3: ='Data Sheet'!G56 -> 44651 | H3: ='Data Sheet'!H56 -> 45016 | I3: ='Data Sheet'!I56 -> 45382 | ... K3: ='Data Sheet'!K56 -> 46112
A4: Equity Share Capital | B4: ='Data Sheet'!B57 -> 1144 | C4: ='Data Sheet'!C57 -> 1088 | D4: ='Data Sheet'!D57 -> 2170 | E4: ='Data Sheet'!E57 -> 2122 | F4: ='Data Sheet'!F57 -> 2124 | G4: ='Data Sheet'!G57 -> 2098 | H4: ='Data Sheet'!H57 -> 2069 | I4: ='Data Sheet'!I57 -> 2071 | ... K4: ='Data Sheet'!K57 -> 2024
A5: Reserves | B5: ='Data Sheet'!B58 -> 67838 | C5: ='Data Sheet'!C58 -> 63835 | D5: ='Data Sheet'!D58 -> 62778 | E5: ='Data Sheet'!E58 -> 63328 | F5: ='Data Sheet'!F58 -> 74227 | G5: ='Data Sheet'!G58 -> 73252 | H5: ='Data Sheet'!H58 -> 73338 | I5: ='Data Sheet'!I58 -> 86045 | ... K5: ='Data Sheet'!K58 -> 90828
A6: Borrowings | B6: ='Data Sheet'!B59 -> 0 | C6: ='Data Sheet'!C59 -> 0 | D6: ='Data Sheet'!D59 -> 0 | E6: ='Data Sheet'!E59 -> 4633 | F6: ='Data Sheet'!F59 -> 5325 | G6: ='Data Sheet'!G59 -> 5474 | H6: ='Data Sheet'!H59 -> 8299 | I6: ='Data Sheet'!I59 -> 8359 | ... K6: ='Data Sheet'!K59 -> 9176
A7: Other Liabilities | B7: ='Data Sheet'!B60 -> 14166 | C7: ='Data Sheet'!C60 -> 14426 | D7: ='Data Sheet'!D60 -> 19118 | E7: ='Data Sheet'!E60 -> 21717 | F7: ='Data Sheet'!F60 -> 25835 | G7: ='Data Sheet'!G60 -> 35905 | H7: ='Data Sheet'!H60 -> 40890 | I7: ='Data Sheet'!I60 -> 39545 | ... K7: ='Data Sheet'!K60 -> 52260
A8: Total | B8: ='Data Sheet'!B61 -> 83148 | C8: ='Data Sheet'!C61 -> 79349 | D8: ='Data Sheet'!D61 -> 84066 | E8: ='Data Sheet'!E61 -> 91800 | F8: ='Data Sheet'!F61 -> 107511 | G8: ='Data Sheet'!G61 -> 116729 | H8: ='Data Sheet'!H61 -> 124596 | I8: ='Data Sheet'!I61 -> 136020 | ... K8: ='Data Sheet'!K61 -> 154288
A10: Net Block | B10: ='Data Sheet'!B62 -> 14179 | C10: ='Data Sheet'!C62 -> 12574 | D10: ='Data Sheet'!D62 -> 15710 | E10: ='Data Sheet'!E62 -> 23789 | F10: ='Data Sheet'!F62 -> 25505 | G10: ='Data Sheet'!G62 -> 25800 | H10: ='Data Sheet'!H62 -> 29225 | I10: ='Data Sheet'!I62 -> 27622 | ... K10: ='Data Sheet'!K62 -> 33770
A11: Capital Work in Progress | B11: ='Data Sheet'!B63 -> 1365 | C11: ='Data Sheet'!C63 -> 1606 | D11: ='Data Sheet'!D63 -> 1388 | E11: ='Data Sheet'!E63 -> 954 | F11: ='Data Sheet'!F63 -> 922 | G11: ='Data Sheet'!G63 -> 416 | H11: ='Data Sheet'!H63 -> 288 | I11: ='Data Sheet'!I63 -> 293 | ... K11: ='Data Sheet'!K63 -> 526
A12: Investments | B12: ='Data Sheet'!B64 -> 16423 | C12: ='Data Sheet'!C64 -> 12163 | D12: ='Data Sheet'!D64 -> 11261 | E12: ='Data Sheet'!E64 -> 8792 | F12: ='Data Sheet'!F64 -> 14205 | G12: ='Data Sheet'!G64 -> 20324 | H12: ='Data Sheet'!H64 -> 19478 | I12: ='Data Sheet'!I64 -> 24623 | ... K12: ='Data Sheet'!K64 -> 21880
A13: Other Assets | B13: ='Data Sheet'!B65 -> 51181 | C13: ='Data Sheet'!C65 -> 53006 | D13: ='Data Sheet'!D65 -> 55707 | E13: ='Data Sheet'!E65 -> 58265 | F13: ='Data Sheet'!F65 -> 66879 | G13: ='Data Sheet'!G65 -> 70189 | H13: ='Data Sheet'!H65 -> 75605 | I13: ='Data Sheet'!I65 -> 83482 | ... K13: ='Data Sheet'!K65 -> 98112
A14: Total | B14: ='Data Sheet'!B66 -> 83148 | C14: ='Data Sheet'!C66 -> 79349 | D14: ='Data Sheet'!D66 -> 84066 | E14: ='Data Sheet'!E66 -> 91800 | F14: ='Data Sheet'!F66 -> 107511 | G14: ='Data Sheet'!G66 -> 116729 | H14: ='Data Sheet'!H66 -> 124596 | I14: ='Data Sheet'!I66 -> 136020 | ... K14: ='Data Sheet'!K66 -> 154288
A16: Working Capital | B16: =B13-B7 -> 37015 | C16: =C13-C7 -> 38580 | D16: =D13-D7 -> 36589 | E16: =E13-E7 -> 36548 | F16: =F13-F7 -> 41044 | G16: =G13-G7 -> 34284 | H16: =H13-H7 -> 34715 | I16: =I13-I7 -> 43937 | ... K16: =K13-K7 -> 45852
A17: Debtors | B17: ='Data Sheet'!B67 -> 12322 | C17: ='Data Sheet'!C67 -> 13142 | D17: ='Data Sheet'!D67 -> 14827 | E17: ='Data Sheet'!E67 -> 18487 | F17: ='Data Sheet'!F67 -> 19294 | G17: ='Data Sheet'!G67 -> 22698 | H17: ='Data Sheet'!H67 -> 25424 | I17: ='Data Sheet'!I67 -> 30193 | ... K17: ='Data Sheet'!K67 -> 35234
A18: Inventory | B18: ='Data Sheet'!B68 -> 0 | C18: ='Data Sheet'!C68 -> 0 | D18: ='Data Sheet'!D68 -> 0 | E18: ='Data Sheet'!E68 -> 0 | F18: ='Data Sheet'!F68 -> 0 | G18: ='Data Sheet'!G68 -> 0 | H18: ='Data Sheet'!H68 -> 0 | I18: ='Data Sheet'!I68 -> 0 | ... K18: ='Data Sheet'!K68 -> 0
A20: Debtor Days | B20: =IF('Profit & Loss'!B4>0,'Balance Sheet'!B17/('Profit & Loss'!B4/365),0) -> 65.672712 | C20: =IF('Profit & Loss'!C4>0,'Balance Sheet'!C17/('Profit & Loss'!C4/365),0) -> 68.018916 | D20: =IF('Profit & Loss'!D4>0,'Balance Sheet'!D17/('Profit & Loss'!D4/365),0) -> 65.459389 | E20: =IF('Profit & Loss'!E4>0,'Balance Sheet'!E17/('Profit & Loss'!E4/365),0) -> 74.321849 | F20: =IF('Profit & Loss'!F4>0,'Balance Sheet'!F17/('Profit & Loss'!F4/365),0) -> 70.092265 | G20: =IF('Profit & Loss'!G4>0,'Balance Sheet'!G17/('Profit & Loss'!G4/365),0) -> 68.108368 | H20: =IF('Profit & Loss'!H4>0,'Balance Sheet'!H17/('Profit & Loss'!H4/365),0) -> 63.227837 | I20: =IF('Profit & Loss'!I4>0,'Balance Sheet'!I17/('Profit & Loss'!I4/365),0) -> 71.715006 | ... K20: =IF('Profit & Loss'!K4>0,'Balance Sheet'!K17/('Profit & Loss'!K4/365),0) -> 71.986622
A21: Inventory Turnover | B21: =IF('Balance Sheet'!B18>0,'Profit & Loss'!B4/'Balance Sheet'!B18,0) -> 0 | C21: =IF('Balance Sheet'!C18>0,'Profit & Loss'!C4/'Balance Sheet'!C18,0) -> 0 | D21: =IF('Balance Sheet'!D18>0,'Profit & Loss'!D4/'Balance Sheet'!D18,0) -> 0 | E21: =IF('Balance Sheet'!E18>0,'Profit & Loss'!E4/'Balance Sheet'!E18,0) -> 0 | F21: =IF('Balance Sheet'!F18>0,'Profit & Loss'!F4/'Balance Sheet'!F18,0) -> 0 | G21: =IF('Balance Sheet'!G18>0,'Profit & Loss'!G4/'Balance Sheet'!G18,0) -> 0 | H21: =IF('Balance Sheet'!H18>0,'Profit & Loss'!H4/'Balance Sheet'!H18,0) -> 0 | I21: =IF('Balance Sheet'!I18>0,'Profit & Loss'!I4/'Balance Sheet'!I18,0) -> 0 | ... K21: =IF('Balance Sheet'!K18>0,'Profit & Loss'!K4/'Balance Sheet'!K18,0) -> 0
A23: Return on Equity | B23: =IF(SUM('Balance Sheet'!B4:B5)>0,'Profit & Loss'!B12/SUM('Balance Sheet'!B4:B5),"") -> 0.20806877 | C23: =IF(SUM('Balance Sheet'!C4:C5)>0,'Profit & Loss'!C12/SUM('Balance Sheet'!C4:C5),"") -> 0.24689247 | D23: =IF(SUM('Balance Sheet'!D4:D5)>0,'Profit & Loss'!D12/SUM('Balance Sheet'!D4:D5),"") -> 0.23717435 | E23: =IF(SUM('Balance Sheet'!E4:E5)>0,'Profit & Loss'!E12/SUM('Balance Sheet'!E4:E5),"") -> 0.25353705 | F23: =IF(SUM('Balance Sheet'!F4:F5)>0,'Profit & Loss'!F12/SUM('Balance Sheet'!F4:F5),"") -> 0.25344789 | G23: =IF(SUM('Balance Sheet'!G4:G5)>0,'Profit & Loss'!G12/SUM('Balance Sheet'!G4:G5),"") -> 0.29343066 | H23: =IF(SUM('Balance Sheet'!H4:H5)>0,'Profit & Loss'!H12/SUM('Balance Sheet'!H4:H5),"") -> 0.31953267 | I23: =IF(SUM('Balance Sheet'!I4:I5)>0,'Profit & Loss'!I12/SUM('Balance Sheet'!I4:I5),"") -> 0.29770984 | ... K23: =IF(SUM('Balance Sheet'!K4:K5)>0,'Profit & Loss'!K12/SUM('Balance Sheet'!K4:K5),"") -> 0.31706371
A24: Return on Capital Emp | C24: =IF((B4+B5+B6+C4+C5+C6)>0,('Profit & Loss'!C10+'Profit & Loss'!C9)*2/(B4+B5+B6+C4+C5+C6),"") -> 0.30275195 | D24: =IF((C4+C5+C6+D4+D5+D6)>0,('Profit & Loss'!D10+'Profit & Loss'!D9)*2/(C4+C5+C6+D4+D5+D6),"") -> 0.32402923 | E24: =IF((D4+D5+D6+E4+E5+E6)>0,('Profit & Loss'!E10+'Profit & Loss'!E9)*2/(D4+D5+D6+E4+E5+E6),"") -> 0.32847272 | F24: =IF((E4+E5+E6+F4+F5+F6)>0,('Profit & Loss'!F10+'Profit & Loss'!F9)*2/(E4+E5+E6+F4+F5+F6),"") -> 0.35349469 | G24: =IF((F4+F5+F6+G4+G5+G6)>0,('Profit & Loss'!G10+'Profit & Loss'!G9)*2/(F4+F5+F6+G4+G5+G6),"") -> 0.37304615 | H24: =IF((G4+G5+G6+H4+H5+H6)>0,('Profit & Loss'!H10+'Profit & Loss'!H9)*2/(G4+G5+G6+H4+H5+H6),"") -> 0.40850909 | I24: =IF((H4+H5+H6+I4+I5+I6)>0,('Profit & Loss'!I10+'Profit & Loss'!I9)*2/(H4+H5+H6+I4+I5+I6),"") -> 0.40468196 | J24: =IF((I4+I5+I6+J4+J5+J6)>0,('Profit & Loss'!J10+'Profit & Loss'!J9)*2/(I4+I5+I6+J4+J5+J6),"") -> 0.37925394 | K24: =IF((J4+J5+J6+K4+K5+K6)>0,('Profit & Loss'!K10+'Profit & Loss'!K9)*2/(J4+J5+J6+K4+K5+K6),"") -> 0.39220082

Sheet Cash Flow
A1: ='Balance Sheet'!A1 -> INFOSYS LTD | E1: =UPDATE | J1: SCREENER.IN
A3: Narration | B3: ='Data Sheet'!B81 -> 42825 | C3: ='Data Sheet'!C81 -> 43190 | D3: ='Data Sheet'!D81 -> 43555 | E3: ='Data Sheet'!E81 -> 43921 | F3: ='Data Sheet'!F81 -> 44286 | G3: ='Data Sheet'!G81 -> 44651 | H3: ='Data Sheet'!H81 -> 45016 | I3: ='Data Sheet'!I81 -> 45382 | ... K3: ='Data Sheet'!K81 -> 46112
A4: Cash from Operating Activity | B4: ='Data Sheet'!B82 -> 11531 | C4: ='Data Sheet'!C82 -> 13218 | D4: ='Data Sheet'!D82 -> 14841 | E4: ='Data Sheet'!E82 -> 17003 | F4: ='Data Sheet'!F82 -> 23224 | G4: ='Data Sheet'!G82 -> 23885 | H4: ='Data Sheet'!H82 -> 22467 | I4: ='Data Sheet'!I82 -> 25210 | ... K4: ='Data Sheet'!K82 -> 33986
A5: Cash from Investing Activity | B5: ='Data Sheet'!B83 -> -14664 | C5: ='Data Sheet'!C83 -> 4533 | D5: ='Data Sheet'!D83 -> -632 | E5: ='Data Sheet'!E83 -> -331 | F5: ='Data Sheet'!F83 -> -7373 | G5: ='Data Sheet'!G83 -> -6485 | H5: ='Data Sheet'!H83 -> -1071 | I5: ='Data Sheet'!I83 -> -5093 | ... K5: ='Data Sheet'!K83 -> 3546
A6: Cash from Financing Activity | B6: ='Data Sheet'!B84 -> -6939 | C6: ='Data Sheet'!C84 -> -20505 | D6: ='Data Sheet'!D84 -> -14512 | E6: ='Data Sheet'!E84 -> -17591 | F6: ='Data Sheet'!F84 -> -9786 | G6: ='Data Sheet'!G84 -> -24642 | H6: ='Data Sheet'!H84 -> -26695 | I6: ='Data Sheet'!I84 -> -17504 | ... K6: ='Data Sheet'!K84 -> -39786
A7: Net Cash Flow | B7: ='Data Sheet'!B85 -> -10072 | C7: ='Data Sheet'!C85 -> -2754 | D7: ='Data Sheet'!D85 -> -303 | E7: ='Data Sheet'!E85 -> -919 | F7: ='Data Sheet'!F85 -> 6065 | G7: ='Data Sheet'!G85 -> -7242 | H7: ='Data Sheet'!H85 -> -5299 | I7: ='Data Sheet'!I85 -> 2613 | ... K7: ='Data Sheet'!K85 -> -2254

Sheet Customization
A1: How to use it?
A3: You can customize this workbook as you want.
B4: You can add custom formating, add conditional formating, add your own formulas… do ANYTHING.
B5: Please don't edit the "Data Sheet" only.
A7: After customization, you can upload this back on Screener.
B8: Upload on: | C8: https://www.screener.in/excel/
A10: Download your customized workbooks now onwards.
B11: Now whenever you will "Export to excel" from Screener, it will export your customized file.
A14: TESTING:
B15: This is a testing feature currently.
B16: You can report any formula errors on the worksheet at: support@screener.in

Sheet Data Sheet
A1: COMPANY NAME | B1: INFOSYS LTD | E1: =IF(B2<>B3, "A NEW VERSION OF THE WORKSHEET IS AVAILABLE", "")
A2: LATEST VERSION | B2: 2.1 | E2: PLEASE DO NOT MAKE ANY CHANGES TO THIS SHEET
A3: CURRENT VERSION | B3: 2.1
A5: META
A6: Number of shares | B6: =IF(B9>0, B9/B8, 0) -> 405.82324
A7: Face Value | B7: 5
A8: Current Price | B8: 1037.7
A9: Market Capitalization | B9: 421122.78
A15: PROFIT & LOSS
A16: Report Date | B16: 42825 | C16: 43190 | D16: 43555 | E16: 43921 | F16: 44286 | G16: 44651 | H16: 45016 | I16: 45382 | J16: 45747 | K16: 46112
A17: Sales | B17: 68484 | C17: 70522 | D17: 82675 | E17: 90791 | F17: 100472 | G17: 121641 | H17: 146767 | I17: 153670 | J17: 162990 | K17: 178650
A18: Raw Material Cost
A19: Change in Inventory
A20: Power and Fuel | B20: 228 | C20: 207 | D20: 221 | E20: 229 | F20: 143 | G20: 132 | H20: 176 | I20: 199 | J20: 222 | K20: 223
A21: Other Mfr. Exp | B21: 6712 | C21: 7286 | D21: 9902 | E21: 11086 | F21: 12800 | G21: 20690 | H21: 26330 | I21: 27195 | J21: 30395 | K21: 32922
A22: Employee Cost | B22: 37669 | C22: 38902 | D22: 45323 | E22: 50895 | F22: 55547 | G22: 63997 | H22: 78374 | I22: 82636 | J22: 85968 | K22: 95112
A23: Selling and admin | B23: 4584 | C23: 4585 | D23: 5553 | E23: 5375 | F23: 3194 | G23: 4305 | H23: 5300 | I23: 5705 | J23: 6039 | K23: 6784
A24: Other Expenses | B24: 687 | C24: 720 | D24: 1506 | E24: 939 | F24: 899 | G24: 1026 | H24: 1457 | I24: 1510 | J24: 1130 | K24: 1329
A25: Other Income | B25: 3050 | C25: 3311 | D25: 2882 | E25: 2803 | F25: 2201 | G25: 2295 | H25: 2701 | I25: 4711 | J25: 3600 | K25: 3033
A26: Depreciation | B26: 1703 | C26: 1863 | D26: 2011 | E26: 2893 | F26: 3267 | G26: 3476 | H26: 4225 | I26: 4678 | J26: 4812 | K26: 4902
A27: Interest | E27: 170 | F27: 195 | G27: 200 | H27: 284 | I27: 470 | J27: 416 | K27: 416
A28: Profit before tax | B28: 19951 | C28: 20270 | D28: 21041 | E28: 22007 | F28: 26628 | G28: 30110 | H28: 33322 | I28: 35988 | J28: 37608 | K28: 39995
A29: Tax | B29: 5598 | C29: 4241 | D29: 5631 | E29: 5368 | F29: 7205 | G29: 7964 | H29: 9214 | I29: 9740 | J29: 10858 | K29: 10521
A30: Net profit | B30: 14353 | C30: 16029 | D30: 15404 | E30: 16594 | F30: 19351 | G30: 22110 | H30: 24095 | I30: 26233 | J30: 26713 | K30: 29440
A31: Dividend Amount | B31: 5891.6 | C31: 9465.6 | D31: 9222.5 | E31: 7427 | F31: 11469.6 | G31: 13007.6 | H31: 14069.2 | I31: 19053.2 | J31: 17827.8 | K31: 19430.4
A40: Quarters
A41: Report Date | B41: 45382 | C41: 45473 | D41: 45565 | E41: 45657 | F41: 45747 | G41: 45838 | H41: 45930 | I41: 46022 | J41: 46112 | K41: 46203
A42: Sales | B42: 37923 | C42: 39315 | D42: 40986 | E42: 41764 | F42: 40925 | G42: 42279 | H42: 44490 | I42: 45479 | J42: 46402 | K42: 48211
A43: Expenses | B43: 29139 | C43: 29878 | D43: 31177 | E43: 31649 | F43: 31051 | G43: 32336 | H43: 33955 | I43: 34845 | J43: 35235 | K43: 36802
A44: Other Income | B44: 2729 | C44: 838 | D44: 712 | E44: 859 | F44: 1190 | G44: 1042 | H44: 982 | I44: -150 | J44: 1159 | K44: 984
A45: Depreciation | B45: 1163 | C45: 1149 | D45: 1160 | E45: 1203 | F45: 1299 | G45: 1140 | H45: 1182 | I45: 1155 | J45: 1424 | K45: 1246
A46: Interest | B46: 110 | C46: 105 | D46: 108 | E46: 101 | F46: 102 | G46: 105 | H46: 106 | I46: 100 | J46: 105 | K46: 119
A47: Profit before tax | B47: 10240 | C47: 9021 | D47: 9253 | E47: 9670 | F47: 9663 | G47: 9740 | H47: 10229 | I47: 9229 | J47: 10797 | K47: 11028
A48: Tax | B48: 2265 | C48: 2647 | D48: 2737 | E48: 2848 | F48: 2625 | G48: 2816 | H48: 2854 | I48: 2563 | J48: 2288 | K48: 3253
A49: Net profit | B49: 7969 | C49: 6368 | D49: 6506 | E49: 6806 | F49: 7033 | G49: 6921 | H49: 7364 | I49: 6654 | J49: 8501 | K49: 7769
A50: Operating Profit | B50: 8784 | C50: 9437 | D50: 9809 | E50: 10115 | F50: 9874 | G50: 9943 | H50: 10535 | I50: 10634 | J50: 11167 | K50: 11409
A55: BALANCE SHEET
A56: Report Date | B56: 42825 | C56: 43190 | D56: 43555 | E56: 43921 | F56: 44286 | G56: 44651 | H56: 45016 | I56: 45382 | J56: 45747 | K56: 46112
A57: Equity Share Capital | B57: 1144 | C57: 1088 | D57: 2170 | E57: 2122 | F57: 2124 | G57: 2098 | H57: 2069 | I57: 2071 | J57: 2073 | K57: 2024
A58: Reserves | B58: 67838 | C58: 63835 | D58: 62778 | E58: 63328 | F58: 74227 | G58: 73252 | H58: 73338 | I58: 86045 | J58: 93745 | K58: 90828
...

Sheet Historical FS
B2: ="Historical Financial Statement - "&'Data Sheet'!B1 -> Historical Financial Statement - INFOSYS LTD
B3: Years | C3: ='Data Sheet'!B16 -> 42825 | D3: ='Data Sheet'!C16 -> 43190 | E3: ='Data Sheet'!D16 -> 43555 | F3: ='Data Sheet'!E16 -> 43921 | G3: ='Data Sheet'!F16 -> 44286 | H3: ='Data Sheet'!G16 -> 44651 | I3: ='Data Sheet'!H16 -> 45016 | J3: ='Data Sheet'!I16 -> 45382 | ... L3: ='Data Sheet'!K16 -> 46112 | M3: LTM
A5: # | B5: Income Statement
B6: Sales | C6: =IFERROR('Data Sheet'!B17,0) -> 68484 | D6: =IFERROR('Data Sheet'!C17,0) -> 70522 | E6: =IFERROR('Data Sheet'!D17,0) -> 82675 | F6: =IFERROR('Data Sheet'!E17,0) -> 90791 | G6: =IFERROR('Data Sheet'!F17,0) -> 100472 | H6: =IFERROR('Data Sheet'!G17,0) -> 121641 | I6: =IFERROR('Data Sheet'!H17,0) -> 146767 | J6: =IFERROR('Data Sheet'!I17,0) -> 153670 | ... L6: =IFERROR('Data Sheet'!K17,0) -> 178650 | M6: =IFERROR(SUM('Data Sheet'!H42:K42),0) -> 184582
B7: Sales Growth | D7: =IFERROR(D6/C6-1,0) -> 0.029758776 | E7: =IFERROR(E6/D6-1,0) -> 0.1723292 | F7: =IFERROR(F6/E6-1,0) -> 0.098167523 | G7: =IFERROR(G6/F6-1,0) -> 0.10662951 | H7: =IFERROR(H6/G6-1,0) -> 0.21069552 | I7: =IFERROR(I6/H6-1,0) -> 0.20655864 | J7: =IFERROR(J6/I6-1,0) -> 0.047033734 | K7: =IFERROR(K6/J6-1,0) -> 0.060649444 | ... M7: =IFERROR(M6/L6-1,0) -> 0.03320459
B9: COGS | C9: =IFERROR(SUM('Data Sheet'!B18,'Data Sheet'!B20:B22)-1*'Data Sheet'!B19,0) -> 44609 | D9: =IFERROR(SUM('Data Sheet'!C18,'Data Sheet'!C20:C22)-1*'Data Sheet'!C19,0) -> 46395 | E9: =IFERROR(SUM('Data Sheet'!D18,'Data Sheet'!D20:D22)-1*'Data Sheet'!D19,0) -> 55446 | F9: =IFERROR(SUM('Data Sheet'!E18,'Data Sheet'!E20:E22)-1*'Data Sheet'!E19,0) -> 62210 | G9: =IFERROR(SUM('Data Sheet'!F18,'Data Sheet'!F20:F22)-1*'Data Sheet'!F19,0) -> 68490 | H9: =IFERROR(SUM('Data Sheet'!G18,'Data Sheet'!G20:G22)-1*'Data Sheet'!G19,0) -> 84819 | I9: =IFERROR(SUM('Data Sheet'!H18,'Data Sheet'!H20:H22)-1*'Data Sheet'!H19,0) -> 104880 | J9: =IFERROR(SUM('Data Sheet'!I18,'Data Sheet'!I20:I22)-1*'Data Sheet'!I19,0) -> 110030 | ... L9: =IFERROR(SUM('Data Sheet'!K18,'Data Sheet'!K20:K22)-1*'Data Sheet'!K19,0) -> 128257 | M9: =IFERROR(SUM('Data Sheet'!H43:K43),0) -> 140837
B10: COGS % Sales | C10: =IFERROR(C9/C6,0) -> 0.65137842 | D10: =IFERROR(D9/D6,0) -> 0.65787981 | E10: =IFERROR(E9/E6,0) -> 0.67065014 | F10: =IFERROR(F9/F6,0) -> 0.68520007 | G10: =IFERROR(G9/G6,0) -> 0.68168246 | H10: =IFERROR(H9/H6,0) -> 0.69728957 | I10: =IFERROR(I9/I6,0) -> 0.71460206 | J10: =IFERROR(J9/J6,0) -> 0.71601484 | ... M10: =IFERROR(M9/M6,0) -> 0.76300506
B12: Gross Profit | C12: =C6-C9 -> 23875 | D12: =D6-D9 -> 24127 | E12: =E6-E9 -> 27229 | F12: =F6-F9 -> 28581 | G12: =G6-G9 -> 31982 | H12: =H6-H9 -> 36822 | I12: =I6-I9 -> 41887 | J12: =J6-J9 -> 43640 | ... M12: =M6-M9 -> 43745
B13: Gross Margin | C13: =IFERROR(C12/C6,0) -> 0.34862158 | D13: =IFERROR(D12/D6,0) -> 0.34212019 | E13: =IFERROR(E12/E6,0) -> 0.32934986 | F13: =IFERROR(F12/F6,0) -> 0.31479993 | G13: =IFERROR(G12/G6,0) -> 0.31831754 | H13: =IFERROR(H12/H6,0) -> 0.30271043 | I13: =IFERROR(I12/I6,0) -> 0.28539794 | J13: =IFERROR(J12/J6,0) -> 0.28398516 | ... M13: =IFERROR(M12/M6,0) -> 0.23699494
B15: Selling & General Expenses | C15: =IFERROR(SUM('Data Sheet'!B23:B24),0) -> 5271 | D15: =IFERROR(SUM('Data Sheet'!C23:C24),0) -> 5305 | E15: =IFERROR(SUM('Data Sheet'!D23:D24),0) -> 7059 | F15: =IFERROR(SUM('Data Sheet'!E23:E24),0) -> 6314 | G15: =IFERROR(SUM('Data Sheet'!F23:F24),0) -> 4093 | H15: =IFERROR(SUM('Data Sheet'!G23:G24),0) -> 5331 | I15: =IFERROR(SUM('Data Sheet'!H23:H24),0) -> 6757 | J15: =IFERROR(SUM('Data Sheet'!I23:I24),0) -> 7215 | ... M15: =IFERROR(SUM('Data Sheet'!L23:L24),0) -> 0
B16: S&G % Sales | C16: =IFERROR(C15/C6,0) -> 0.076966883 | D16: =IFERROR(D15/D6,0) -> 0.075224753 | E16: =IFERROR(E15/E6,0) -> 0.085382522 | F16: =IFERROR(F15/F6,0) -> 0.069544338 | G16: =IFERROR(G15/G6,0) -> 0.040737718 | H16: =IFERROR(H15/H6,0) -> 0.043825684 | I16: =IFERROR(I15/I6,0) -> 0.04603896 | J16: =IFERROR(J15/J6,0) -> 0.046951259 | ... M16: =IFERROR(M15/M6,0) -> 0
B18: EBITDA | C18: =C12-C15 -> 18604 | D18: =D12-D15 -> 18822 | E18: =E12-E15 -> 20170 | F18: =F12-F15 -> 22267 | G18: =G12-G15 -> 27889 | H18: =H12-H15 -> 31491 | I18: =I12-I15 -> 35130 | J18: =J12-J15 -> 36425 | ... M18: =M12-M15 -> 43745
B19: EBITDA Margins | C19: =IFERROR(C18/C6,0) -> 0.27165469 | D19: =IFERROR(D18/D6,0) -> 0.26689544 | E19: =IFERROR(E18/E6,0) -> 0.24396734 | F19: =IFERROR(F18/F6,0) -> 0.24525559 | G19: =IFERROR(G18/G6,0) -> 0.27757982 | H19: =IFERROR(H18/H6,0) -> 0.25888475 | I19: =IFERROR(I18/I6,0) -> 0.23935898 | J19: =IFERROR(J18/J6,0) -> 0.2370339 | ... M19: =IFERROR(M18/M6,0) -> 0.23699494
B21: Interest | C21: =IFERROR(SUM('Data Sheet'!B27),0) -> 0 | D21: =IFERROR(SUM('Data Sheet'!C27),0) -> 0 | E21: =IFERROR(SUM('Data Sheet'!D27),0) -> 0 | F21: =IFERROR(SUM('Data Sheet'!E27),0) -> 170 | G21: =IFERROR(SUM('Data Sheet'!F27),0) -> 195 | H21: =IFERROR(SUM('Data Sheet'!G27),0) -> 200 | I21: =IFERROR(SUM('Data Sheet'!H27),0) -> 284 | J21: =IFERROR(SUM('Data Sheet'!I27),0) -> 470 | ... L21: =IFERROR(SUM('Data Sheet'!K27),0) -> 416 | M21: =IFERROR(SUM('Data Sheet'!H46:K46),0) -> 430
B22: Interest % Sales | C22: =IFERROR(C21/C6,0) -> 0 | D22: =IFERROR(D21/D6,0) -> 0 | E22: =IFERROR(E21/E6,0) -> 0 | F22: =IFERROR(F21/F6,0) -> 0.0018724323 | G22: =IFERROR(G21/G6,0) -> 0.0019408392 | H22: =IFERROR(H21/H6,0) -> 0.0016441825 | I22: =IFERROR(I21/I6,0) -> 0.0019350399 | J22: =IFERROR(J21/J6,0) -> 0.003058502 | ... M22: =IFERROR(M21/M6,0) -> 0.0023295879
B24: Depreciation | C24: =IFERROR('Data Sheet'!B26,0) -> 1703 | D24: =IFERROR('Data Sheet'!C26,0) -> 1863 | E24: =IFERROR('Data Sheet'!D26,0) -> 2011 | F24: =IFERROR('Data Sheet'!E26,0) -> 2893 | G24: =IFERROR('Data Sheet'!F26,0) -> 3267 | H24: =IFERROR('Data Sheet'!G26,0) -> 3476 | I24: =IFERROR('Data Sheet'!H26,0) -> 4225 | J24: =IFERROR('Data Sheet'!I26,0) -> 4678 | ... L24: =IFERROR('Data Sheet'!K26,0) -> 4902 | M24: =IFERROR(SUM('Data Sheet'!H45:K45),0) -> 5007
B25: Depreciation % Sales | C25: =IFERROR(C24/C6,0) -> 0.024867122 | D25: =IFERROR(D24/D6,0) -> 0.026417288 | E25: =IFERROR(E24/E6,0) -> 0.024324161 | F25: =IFERROR(F24/F6,0) -> 0.031864392 | G25: =IFERROR(G24/G6,0) -> 0.032516522 | H25: =IFERROR(H24/H6,0) -> 0.028575891 | I25: =IFERROR(I24/I6,0) -> 0.028787125 | J25: =IFERROR(J24/J6,0) -> 0.030441856 | ... M25: =IFERROR(M24/M6,0) -> 0.027126155
B27: Other Income | C27: =IFERROR('Data Sheet'!B25,0) -> 3050 | D27: =IFERROR('Data Sheet'!C25,0) -> 3311 | E27: =IFERROR('Data Sheet'!D25,0) -> 2882 | F27: =IFERROR('Data Sheet'!E25,0) -> 2803 | G27: =IFERROR('Data Sheet'!F25,0) -> 2201 | H27: =IFERROR('Data Sheet'!G25,0) -> 2295 | I27: =IFERROR('Data Sheet'!H25,0) -> 2701 | J27: =IFERROR('Data Sheet'!I25,0) -> 4711 | ... M27: =IFERROR('Data Sheet'!L25,0) -> 0
B29: Earning Before Tax | C29: =SUM(C18,C27)-SUM(C21,C24) -> 19951 | D29: =SUM(D18,D27)-SUM(D21,D24) -> 20270 | E29: =SUM(E18,E27)-SUM(E21,E24) -> 21041 | F29: =SUM(F18,F27)-SUM(F21,F24) -> 22007 | G29: =SUM(G18,G27)-SUM(G21,G24) -> 26628 | H29: =SUM(H18,H27)-SUM(H21,H24) -> 30110 | I29: =SUM(I18,I27)-SUM(I21,I24) -> 33322 | J29: =SUM(J18,J27)-SUM(J21,J24) -> 35988 | ... M29: =SUM(M18,M27)-SUM(M21,M24) -> 38308
B30: EBT % Sales | C30: =IFERROR(C29/C6,0) -> 0.29132352 | D30: =IFERROR(D29/D6,0) -> 0.28742804 | E30: =IFERROR(E29/E6,0) -> 0.25450257 | F30: =IFERROR(F29/F6,0) -> 0.24239187 | G30: =IFERROR(G29/G6,0) -> 0.26502906 | H30: =IFERROR(H29/H6,0) -> 0.24753167 | I30: =IFERROR(I29/I6,0) -> 0.22704014 | J30: =IFERROR(J29/J6,0) -> 0.23419015 | ... M30: =IFERROR(M29/M6,0) -> 0.2075392
B32: Tax | C32: =IFERROR('Data Sheet'!B29,0) -> 5598 | D32: =IFERROR('Data Sheet'!C29,0) -> 4241 | E32: =IFERROR('Data Sheet'!D29,0) -> 5631 | F32: =IFERROR('Data Sheet'!E29,0) -> 5368 | G32: =IFERROR('Data Sheet'!F29,0) -> 7205 | H32: =IFERROR('Data Sheet'!G29,0) -> 7964 | I32: =IFERROR('Data Sheet'!H29,0) -> 9214 | J32: =IFERROR('Data Sheet'!I29,0) -> 9740 | ... L32: =IFERROR('Data Sheet'!K29,0) -> 10521 | M32: =IFERROR(SUM('Data Sheet'!H48:K48),0) -> 10958
B33: Effective Tax Rate | C33: =IFERROR(C32/C29,0) -> 0.28058744 | D33: =IFERROR(D32/D29,0) -> 0.20922546 | E33: =IFERROR(E32/E29,0) -> 0.26762036 | F33: =IFERROR(F32/F29,0) -> 0.24392239 | G33: =IFERROR(G32/G29,0) -> 0.27057984 | H33: =IFERROR(H32/H29,0) -> 0.26449684 | I33: =IFERROR(I32/I29,0) -> 0.27651401 | J33: =IFERROR(J32/J29,0) -> 0.27064577 | ... M33: =IFERROR(M32/M29,0) -> 0.28604991
B35: Net Profit | C35: =IFERROR(C29-C32,0) -> 14353 | D35: =IFERROR(D29-D32,0) -> 16029 | E35: =IFERROR(E29-E32,0) -> 15410 | F35: =IFERROR(F29-F32,0) -> 16639 | G35: =IFERROR(G29-G32,0) -> 19423 | H35: =IFERROR(H29-H32,0) -> 22146 | I35: =IFERROR(I29-I32,0) -> 24108 | J35: =IFERROR(J29-J32,0) -> 26248 | ... M35: =IFERROR(M29-M32,0) -> 27350
B36: Net Margins | C36: =IFERROR(C35/C6,0) -> 0.2095818 | D36: =IFERROR(D35/D6,0) -> 0.22729077 | E36: =IFERROR(E35/E6,0) -> 0.1863925 | F36: =IFERROR(F35/F6,0) -> 0.18326706 | G36: =IFERROR(G35/G6,0) -> 0.19331754 | H36: =IFERROR(H35/H6,0) -> 0.18206033 | I36: =IFERROR(I35/I6,0) -> 0.16426036 | J36: =IFERROR(J35/J6,0) -> 0.17080757 | ... M36: =IFERROR(M35/M6,0) -> 0.14817263
B38: No. of Equity Shares | C38: =IFERROR('Data Sheet'!B93,0) -> 459.39 | D38: =IFERROR('Data Sheet'!C93,0) -> 436.82 | E38: =IFERROR('Data Sheet'!D93,0) -> 436.89 | F38: =IFERROR('Data Sheet'!E93,0) -> 425.9 | G38: =IFERROR('Data Sheet'!F93,0) -> 426.07 | H38: =IFERROR('Data Sheet'!G93,0) -> 420.67 | I38: =IFERROR('Data Sheet'!H93,0) -> 414.86 | J38: =IFERROR('Data Sheet'!I93,0) -> 415.09 | ... M38: =IFERROR('Data Sheet'!L93,0) -> 0
B40: Earning per Share | C40: =IFERROR(C35/C38,0) -> 31.243606 | D40: =IFERROR(D35/D38,0) -> 36.694748 | E40: =IFERROR(E35/E38,0) -> 35.272036 | F40: =IFERROR(F35/F38,0) -> 39.067856 | G40: =IFERROR(G35/G38,0) -> 45.586406 | H40: =IFERROR(H35/H38,0) -> 52.644591 | I40: =IFERROR(I35/I38,0) -> 58.11117 | J40: =IFERROR(J35/J38,0) -> 63.234479 | ... M40: =IFERROR(M35/M38,0) -> 0
B41: EPS Growth | D41: =IFERROR(D40/C40-1,0) -> 0.17447227 | E41: =IFERROR(E40/D40-1,0) -> -0.038771542 | F41: =IFERROR(F40/E40-1,0) -> 0.10761556 | G41: =IFERROR(G40/F40-1,0) -> 0.16685199 | H41: =IFERROR(H40/G40-1,0) -> 0.15483091 | I41: =IFERROR(I40/H40-1,0) -> 0.10383933 | J41: =IFERROR(J40/I40-1,0) -> 0.088163932 | K41: =IFERROR(K40/J40-1,0) -> 0.018536361 | ... M41: =IFERROR(M40/L40-1,0) -> -1
B43: Dividend per Share | C43: =IFERROR('Data Sheet'!B31/'Historical FS'!C38,0) -> 12.824833 | D43: =IFERROR('Data Sheet'!C31/'Historical FS'!D38,0) -> 21.669337 | E43: =IFERROR('Data Sheet'!D31/'Historical FS'!E38,0) -> 21.109433 | F43: =IFERROR('Data Sheet'!E31/'Historical FS'!F38,0) -> 17.438366 | G43: =IFERROR('Data Sheet'!F31/'Historical FS'!G38,0) -> 26.91952 | H43: =IFERROR('Data Sheet'!G31/'Historical FS'!H38,0) -> 30.92115 | I43: =IFERROR('Data Sheet'!H31/'Historical FS'!I38,0) -> 33.913127 | J43: =IFERROR('Data Sheet'!I31/'Historical FS'!J38,0) -> 45.901371 | ... M43: =IFERROR('Data Sheet'!L31/'Historical FS'!M38,0) -> 0
B44: Dividend Payout Ratio | C44: =IFERROR(C43/C40,0) -> 0.41047865 | D44: =IFERROR(D43/D40,0) -> 0.59052966 | E44: =IFERROR(E43/E40,0) -> 0.59847502 | F44: =IFERROR(F43/F40,0) -> 0.44636096 | G44: =IFERROR(G43/G40,0) -> 0.5905164 | H44: =IFERROR(H43/H40,0) -> 0.58735663 | I44: =IFERROR(I43/I40,0) -> 0.58359051 | J44: =IFERROR(J43/J40,0) -> 0.7258915 | ... M44: =IFERROR(M43/M40,0) -> 0
B46: Retained Earning | C46: =IFERROR(IF(C40>C43,1-C44,0),0) -> 0.58952135 | D46: =IFERROR(IF(D40>D43,1-D44,0),0) -> 0.40947034 | E46: =IFERROR(IF(E40>E43,1-E44,0),0) -> 0.40152498 | F46: =IFERROR(IF(F40>F43,1-F44,0),0) -> 0.55363904 | G46: =IFERROR(IF(G40>G43,1-G44,0),0) -> 0.4094836 | H46: =IFERROR(IF(H40>H43,1-H44,0),0) -> 0.41264337 | I46: =IFERROR(IF(I40>I43,1-I44,0),0) -> 0.41640949 | J46: =IFERROR(IF(J40>J43,1-J44,0),0) -> 0.2741085 | ... M46: =IFERROR(IF(M40>M43,1-M44,0),0) -> 0
A48: # | B48: Balance Sheet
B49: Equity Share Capital | C49: =IFERROR('Data Sheet'!B57,0) -> 1144 | D49: =IFERROR('Data Sheet'!C57,0) -> 1088 | E49: =IFERROR('Data Sheet'!D57,0) -> 2170 | F49: =IFERROR('Data Sheet'!E57,0) -> 2122 | G49: =IFERROR('Data Sheet'!F57,0) -> 2124 | H49: =IFERROR('Data Sheet'!G57,0) -> 2098 | I49: =IFERROR('Data Sheet'!H57,0) -> 2069 | J49: =IFERROR('Data Sheet'!I57,0) -> 2071 | ... L49: =IFERROR('Data Sheet'!K57,0) -> 2024
B50: Reserves | C50: =IFERROR('Data Sheet'!B58,0) -> 67838 | D50: =IFERROR('Data Sheet'!C58,0) -> 63835 | E50: =IFERROR('Data Sheet'!D58,0) -> 62778 | F50: =IFERROR('Data Sheet'!E58,0) -> 63328 | G50: =IFERROR('Data Sheet'!F58,0) -> 74227 | H50: =IFERROR('Data Sheet'!G58,0) -> 73252 | I50: =IFERROR('Data Sheet'!H58,0) -> 73338 | J50: =IFERROR('Data Sheet'!I58,0) -> 86045 | ... L50: =IFERROR('Data Sheet'!K58,0) -> 90828
B51: Borrowings | C51: =IFERROR('Data Sheet'!B59,0) -> 0 | D51: =IFERROR('Data Sheet'!C59,0) -> 0 | E51: =IFERROR('Data Sheet'!D59,0) -> 0 | F51: =IFERROR('Data Sheet'!E59,0) -> 4633 | G51: =IFERROR('Data Sheet'!F59,0) -> 5325 | H51: =IFERROR('Data Sheet'!G59,0) -> 5474 | I51: =IFERROR('Data Sheet'!H59,0) -> 8299 | J51: =IFERROR('Data Sheet'!I59,0) -> 8359 | ... L51: =IFERROR('Data Sheet'!K59,0) -> 9176
B52: Other Liabilities | C52: =IFERROR('Data Sheet'!B60,0) -> 14166 | D52: =IFERROR('Data Sheet'!C60,0) -> 14426 | E52: =IFERROR('Data Sheet'!D60,0) -> 19118 | F52: =IFERROR('Data Sheet'!E60,0) -> 21717 | G52: =IFERROR('Data Sheet'!F60,0) -> 25835 | H52: =IFERROR('Data Sheet'!G60,0) -> 35905 | I52: =IFERROR('Data Sheet'!H60,0) -> 40890 | J52: =IFERROR('Data Sheet'!I60,0) -> 39545 | ... L52: =IFERROR('Data Sheet'!K60,0) -> 52260
B53: Total Liability | C53: =IFERROR('Data Sheet'!B61,0) -> 83148 | D53: =IFERROR('Data Sheet'!C61,0) -> 79349 | E53: =IFERROR('Data Sheet'!D61,0) -> 84066 | F53: =IFERROR('Data Sheet'!E61,0) -> 91800 | G53: =IFERROR('Data Sheet'!F61,0) -> 107511 | H53: =IFERROR('Data Sheet'!G61,0) -> 116729 | I53: =IFERROR('Data Sheet'!H61,0) -> 124596 | J53: =IFERROR('Data Sheet'!I61,0) -> 136020 | ... L53: =IFERROR('Data Sheet'!K61,0) -> 154288
B55: Fixed Asset Net Block | C55: =IFERROR('Data Sheet'!B62,0) -> 14179 | D55: =IFERROR('Data Sheet'!C62,0) -> 12574 | E55: =IFERROR('Data Sheet'!D62,0) -> 15710 | F55: =IFERROR('Data Sheet'!E62,0) -> 23789 | G55: =IFERROR('Data Sheet'!F62,0) -> 25505 | H55: =IFERROR('Data Sheet'!G62,0) -> 25800 | I55: =IFERROR('Data Sheet'!H62,0) -> 29225 | J55: =IFERROR('Data Sheet'!I62,0) -> 27622 | ... L55: =IFERROR('Data Sheet'!K62,0) -> 33770
B56: Capital Work in Progress | C56: =IFERROR('Data Sheet'!B63,0) -> 1365 | D56: =IFERROR('Data Sheet'!C63,0) -> 1606 | E56: =IFERROR('Data Sheet'!D63,0) -> 1388 | F56: =IFERROR('Data Sheet'!E63,0) -> 954 | G56: =IFERROR('Data Sheet'!F63,0) -> 922 | H56: =IFERROR('Data Sheet'!G63,0) -> 416 | I56: =IFERROR('Data Sheet'!H63,0) -> 288 | J56: =IFERROR('Data Sheet'!I63,0) -> 293 | ... L56: =IFERROR('Data Sheet'!K63,0) -> 526
B57: Investments | C57: =IFERROR('Data Sheet'!B64,0) -> 16423 | D57: =IFERROR('Data Sheet'!C64,0) -> 12163 | E57: =IFERROR('Data Sheet'!D64,0) -> 11261 | F57: =IFERROR('Data Sheet'!E64,0) -> 8792 | G57: =IFERROR('Data Sheet'!F64,0) -> 14205 | H57: =IFERROR('Data Sheet'!G64,0) -> 20324 | I57: =IFERROR('Data Sheet'!H64,0) -> 19478 | J57: =IFERROR('Data Sheet'!I64,0) -> 24623 | ... L57: =IFERROR('Data Sheet'!K64,0) -> 21880
B58: Other Assets | C58: =IFERROR('Data Sheet'!B65-SUM('Data Sheet'!B67:B69),0) -> 16234 | D58: =IFERROR('Data Sheet'!C65-SUM('Data Sheet'!C67:C69),0) -> 20046 | E58: =IFERROR('Data Sheet'!D65-SUM('Data Sheet'!D67:D69),0) -> 21312 | F58: =IFERROR('Data Sheet'!E65-SUM('Data Sheet'!E67:E69),0) -> 21129 | G58: =IFERROR('Data Sheet'!F65-SUM('Data Sheet'!F67:F69),0) -> 22871 | H58: =IFERROR('Data Sheet'!G65-SUM('Data Sheet'!G67:G69),0) -> 30019 | I58: =IFERROR('Data Sheet'!H65-SUM('Data Sheet'!H67:H69),0) -> 38008 | J58: =IFERROR('Data Sheet'!I65-SUM('Data Sheet'!I67:I69),0) -> 38503 | ... L58: =IFERROR('Data Sheet'!K65-SUM('Data Sheet'!K67:K69),0) -> 40677
...

Sheet Ratio Analysis 
B2: ="Ratio Analysis - "&'Data Sheet'!B1 -> Ratio Analysis - INFOSYS LTD
B3: Years | C3: ='Data Sheet'!B16 -> 42825 | D3: ='Data Sheet'!C16 -> 43190 | E3: ='Data Sheet'!D16 -> 43555 | F3: ='Data Sheet'!E16 -> 43921 | G3: ='Data Sheet'!F16 -> 44286 | H3: ='Data Sheet'!G16 -> 44651 | I3: ='Data Sheet'!H16 -> 45016 | J3: ='Data Sheet'!I16 -> 45382 | ... L3: ='Data Sheet'!K16 -> 46112 | M3: Trends | N3: Mean | O3: Median
B5: Sales Growth | D5: =IFERROR('Historical FS'!D6/'Historical FS'!C6-1,0) -> 0.029758776 | E5: =IFERROR('Historical FS'!E6/'Historical FS'!D6-1,0) -> 0.1723292 | F5: =IFERROR('Historical FS'!F6/'Historical FS'!E6-1,0) -> 0.098167523 | G5: =IFERROR('Historical FS'!G6/'Historical FS'!F6-1,0) -> 0.10662951 | H5: =IFERROR('Historical FS'!H6/'Historical FS'!G6-1,0) -> 0.21069552 | I5: =IFERROR('Historical FS'!I6/'Historical FS'!H6-1,0) -> 0.20655864 | J5: =IFERROR('Historical FS'!J6/'Historical FS'!I6-1,0) -> 0.047033734 | K5: =IFERROR('Historical FS'!K6/'Historical FS'!J6-1,0) -> 0.060649444 | L5: =IFERROR('Historical FS'!L6/'Historical FS'!K6-1,0) -> 0.096079514 | N5: =IFERROR(AVERAGE(D5:L5),0) -> 0.11421132 | O5: =IFERROR(MEDIAN(C5:L5),0) -> 0.098167523
B6: EBITDA Growth | D6: =IFERROR('Historical FS'!D18/'Historical FS'!C18-1,0) -> 0.01171791 | E6: =IFERROR('Historical FS'!E18/'Historical FS'!D18-1,0) -> 0.071618319 | F6: =IFERROR('Historical FS'!F18/'Historical FS'!E18-1,0) -> 0.10396629 | G6: =IFERROR('Historical FS'!G18/'Historical FS'!F18-1,0) -> 0.25248125 | H6: =IFERROR('Historical FS'!H18/'Historical FS'!G18-1,0) -> 0.12915486 | I6: =IFERROR('Historical FS'!I18/'Historical FS'!H18-1,0) -> 0.11555683 | J6: =IFERROR('Historical FS'!J18/'Historical FS'!I18-1,0) -> 0.03686308 | K6: =IFERROR('Historical FS'!K18/'Historical FS'!J18-1,0) -> 0.077172272 | L6: =IFERROR('Historical FS'!L18/'Historical FS'!K18-1,0) -> 0.077581813 | N6: =IFERROR(AVERAGE(D6:L6),0) -> 0.097345847 | O6: =IFERROR(MEDIAN(C6:L6),0) -> 0.077581813
B7: EBT Growth | D7: =IFERROR('Historical FS'!D29/'Historical FS'!C29-1,0) -> 0.015989173 | E7: =IFERROR('Historical FS'!E29/'Historical FS'!D29-1,0) -> 0.038036507 | F7: =IFERROR('Historical FS'!F29/'Historical FS'!E29-1,0) -> 0.045910365 | G7: =IFERROR('Historical FS'!G29/'Historical FS'!F29-1,0) -> 0.20997864 | H7: =IFERROR('Historical FS'!H29/'Historical FS'!G29-1,0) -> 0.13076461 | I7: =IFERROR('Historical FS'!I29/'Historical FS'!H29-1,0) -> 0.10667552 | J7: =IFERROR('Historical FS'!J29/'Historical FS'!I29-1,0) -> 0.080007202 | K7: =IFERROR('Historical FS'!K29/'Historical FS'!J29-1,0) -> 0.045015005 | L7: =IFERROR('Historical FS'!L29/'Historical FS'!K29-1,0) -> 0.063470538 | N7: =IFERROR(AVERAGE(D7:L7),0) -> 0.081760841 | O7: =IFERROR(MEDIAN(C7:L7),0) -> 0.063470538
B8: Net Profit Growth | D8: =IFERROR('Historical FS'!D35/'Historical FS'!C35-1,0) -> 0.11677001 | E8: =IFERROR('Historical FS'!E35/'Historical FS'!D35-1,0) -> -0.038617506 | F8: =IFERROR('Historical FS'!F35/'Historical FS'!E35-1,0) -> 0.079753407 | G8: =IFERROR('Historical FS'!G35/'Historical FS'!F35-1,0) -> 0.16731775 | H8: =IFERROR('Historical FS'!H35/'Historical FS'!G35-1,0) -> 0.14019461 | I8: =IFERROR('Historical FS'!I35/'Historical FS'!H35-1,0) -> 0.088593877 | J8: =IFERROR('Historical FS'!J35/'Historical FS'!I35-1,0) -> 0.088767214 | K8: =IFERROR('Historical FS'!K35/'Historical FS'!J35-1,0) -> 0.019125267 | L8: =IFERROR('Historical FS'!L35/'Historical FS'!K35-1,0) -> 0.10183178 | N8: =IFERROR(AVERAGE(D8:L8),0) -> 0.084859601 | O8: =IFERROR(MEDIAN(C8:L8),0) -> 0.088767214
B9: Dividend Growth | D9: =IFERROR('Historical FS'!D43/'Historical FS'!C43-1,0) -> 0.68963897 | E9: =IFERROR('Historical FS'!E43/'Historical FS'!D43-1,0) -> -0.02583858 | F9: =IFERROR('Historical FS'!F43/'Historical FS'!E43-1,0) -> -0.17390646 | G9: =IFERROR('Historical FS'!G43/'Historical FS'!F43-1,0) -> 0.54369512 | H9: =IFERROR('Historical FS'!H43/'Historical FS'!G43-1,0) -> 0.14865158 | I9: =IFERROR('Historical FS'!I43/'Historical FS'!H43-1,0) -> 0.096761529 | J9: =IFERROR('Historical FS'!J43/'Historical FS'!I43-1,0) -> 0.35349861 | K9: =IFERROR('Historical FS'!K43/'Historical FS'!J43-1,0) -> -0.064855345 | L9: =IFERROR('Historical FS'!L43/'Historical FS'!K43-1,0) -> 0.116149 | N9: =IFERROR(AVERAGE(D9:L9),0) -> 0.18708827 | O9: =IFERROR(MEDIAN(C9:L9),0) -> 0.116149
B11: Gross Margin | C11: =IFERROR('Historical FS'!C13,0) -> 0.34862158 | D11: =IFERROR('Historical FS'!D13,0) -> 0.34212019 | E11: =IFERROR('Historical FS'!E13,0) -> 0.32934986 | F11: =IFERROR('Historical FS'!F13,0) -> 0.31479993 | G11: =IFERROR('Historical FS'!G13,0) -> 0.31831754 | H11: =IFERROR('Historical FS'!H13,0) -> 0.30271043 | I11: =IFERROR('Historical FS'!I13,0) -> 0.28539794 | J11: =IFERROR('Historical FS'!J13,0) -> 0.28398516 | ... L11: =IFERROR('Historical FS'!L13,0) -> 0.28207669 | N11: =IFERROR(AVERAGE(C11:L11),0) -> 0.309209 | O11: =IFERROR(MEDIAN(C11:L11),0) -> 0.30875518
B12: EBITDA Margin | C12: =IFERROR('Historical FS'!C19,0) -> 0.27165469 | D12: =IFERROR('Historical FS'!D19,0) -> 0.26689544 | E12: =IFERROR('Historical FS'!E19,0) -> 0.24396734 | F12: =IFERROR('Historical FS'!F19,0) -> 0.24525559 | G12: =IFERROR('Historical FS'!G19,0) -> 0.27757982 | H12: =IFERROR('Historical FS'!H19,0) -> 0.25888475 | I12: =IFERROR('Historical FS'!I19,0) -> 0.23935898 | J12: =IFERROR('Historical FS'!J19,0) -> 0.2370339 | ... L12: =IFERROR('Historical FS'!L19,0) -> 0.23666387 | N12: =IFERROR(AVERAGE(C12:L12),0) -> 0.25180208 | O12: =IFERROR(MEDIAN(C12:L12),0) -> 0.24461146
B13: Operating Margin | C13: =IFERROR(('Historical FS'!C18-'Historical FS'!C24)/'Historical FS'!C6,0) -> 0.24678757 | D13: =IFERROR(('Historical FS'!D18-'Historical FS'!D24)/'Historical FS'!D6,0) -> 0.24047815 | E13: =IFERROR(('Historical FS'!E18-'Historical FS'!E24)/'Historical FS'!E6,0) -> 0.21964318 | F13: =IFERROR(('Historical FS'!F18-'Historical FS'!F24)/'Historical FS'!F6,0) -> 0.2133912 | G13: =IFERROR(('Historical FS'!G18-'Historical FS'!G24)/'Historical FS'!G6,0) -> 0.2450633 | H13: =IFERROR(('Historical FS'!H18-'Historical FS'!H24)/'Historical FS'!H6,0) -> 0.23030886 | I13: =IFERROR(('Historical FS'!I18-'Historical FS'!I24)/'Historical FS'!I6,0) -> 0.21057186 | J13: =IFERROR(('Historical FS'!J18-'Historical FS'!J24)/'Historical FS'!J6,0) -> 0.20659205 | ... L13: =IFERROR(('Historical FS'!L18-'Historical FS'!L24)/'Historical FS'!L6,0) -> 0.20922474 | N13: =IFERROR(AVERAGE(C13:L13),0) -> 0.2233264 | O13: =IFERROR(MEDIAN(C13:L13),0) -> 0.21651719
B14: EBT Margin | C14: =IFERROR('Historical FS'!C30,0) -> 0.29132352 | D14: =IFERROR('Historical FS'!D30,0) -> 0.28742804 | E14: =IFERROR('Historical FS'!E30,0) -> 0.25450257 | F14: =IFERROR('Historical FS'!F30,0) -> 0.24239187 | G14: =IFERROR('Historical FS'!G30,0) -> 0.26502906 | H14: =IFERROR('Historical FS'!H30,0) -> 0.24753167 | I14: =IFERROR('Historical FS'!I30,0) -> 0.22704014 | J14: =IFERROR('Historical FS'!J30,0) -> 0.23419015 | ... L14: =IFERROR('Historical FS'!L30,0) -> 0.2238735 | N14: =IFERROR(AVERAGE(C14:L14),0) -> 0.25040486 | O14: =IFERROR(MEDIAN(C14:L14),0) -> 0.24496177
B15: Net Profit Margin | C15: =IFERROR('Historical FS'!C36,0) -> 0.2095818 | D15: =IFERROR('Historical FS'!D36,0) -> 0.22729077 | E15: =IFERROR('Historical FS'!E36,0) -> 0.1863925 | F15: =IFERROR('Historical FS'!F36,0) -> 0.18326706 | G15: =IFERROR('Historical FS'!G36,0) -> 0.19331754 | H15: =IFERROR('Historical FS'!H36,0) -> 0.18206033 | I15: =IFERROR('Historical FS'!I36,0) -> 0.16426036 | J15: =IFERROR('Historical FS'!J36,0) -> 0.17080757 | ... L15: =IFERROR('Historical FS'!L36,0) -> 0.16498181 | N15: =IFERROR(AVERAGE(C15:L15),0) -> 0.18460802 | O15: =IFERROR(MEDIAN(C15:L15),0) -> 0.18266369
B18: SalesExpense % Sales | C18: =IFERROR('Historical FS'!C16,0) -> 0.076966883 | D18: =IFERROR('Historical FS'!D16,0) -> 0.075224753 | E18: =IFERROR('Historical FS'!E16,0) -> 0.085382522 | F18: =IFERROR('Historical FS'!F16,0) -> 0.069544338 | G18: =IFERROR('Historical FS'!G16,0) -> 0.040737718 | H18: =IFERROR('Historical FS'!H16,0) -> 0.043825684 | I18: =IFERROR('Historical FS'!I16,0) -> 0.04603896 | J18: =IFERROR('Historical FS'!J16,0) -> 0.046951259 | ... L18: =IFERROR('Historical FS'!L16,0) -> 0.045412818 | N18: =IFERROR(AVERAGE(C18:L18),0) -> 0.057406923 | O18: =IFERROR(MEDIAN(C18:L18),0) -> 0.046495109
B19: Depreciation % Sales | C19: =IFERROR('Historical FS'!C25,0) -> 0.024867122 | D19: =IFERROR('Historical FS'!D25,0) -> 0.026417288 | E19: =IFERROR('Historical FS'!E25,0) -> 0.024324161 | F19: =IFERROR('Historical FS'!F25,0) -> 0.031864392 | G19: =IFERROR('Historical FS'!G25,0) -> 0.032516522 | H19: =IFERROR('Historical FS'!H25,0) -> 0.028575891 | I19: =IFERROR('Historical FS'!I25,0) -> 0.028787125 | J19: =IFERROR('Historical FS'!J25,0) -> 0.030441856 | ... L19: =IFERROR('Historical FS'!L25,0) -> 0.027439127 | N19: =IFERROR(AVERAGE(C19:L19),0) -> 0.028475677 | O19: =IFERROR(MEDIAN(C19:L19),0) -> 0.028681508
B20: OperatingIncome % Sales | C20: =IFERROR(('Historical FS'!C18-'Historical FS'!C24)/'Historical FS'!C6,0) -> 0.24678757 | D20: =IFERROR(('Historical FS'!D18-'Historical FS'!D24)/'Historical FS'!D6,0) -> 0.24047815 | E20: =IFERROR(('Historical FS'!E18-'Historical FS'!E24)/'Historical FS'!E6,0) -> 0.21964318 | F20: =IFERROR(('Historical FS'!F18-'Historical FS'!F24)/'Historical FS'!F6,0) -> 0.2133912 | G20: =IFERROR(('Historical FS'!G18-'Historical FS'!G24)/'Historical FS'!G6,0) -> 0.2450633 | H20: =IFERROR(('Historical FS'!H18-'Historical FS'!H24)/'Historical FS'!H6,0) -> 0.23030886 | I20: =IFERROR(('Historical FS'!I18-'Historical FS'!I24)/'Historical FS'!I6,0) -> 0.21057186 | J20: =IFERROR(('Historical FS'!J18-'Historical FS'!J24)/'Historical FS'!J6,0) -> 0.20659205 | ... L20: =IFERROR(('Historical FS'!L18-'Historical FS'!L24)/'Historical FS'!L6,0) -> 0.20922474 | N20: =IFERROR(AVERAGE(C20:L20),0) -> 0.2233264 | O20: =IFERROR(MEDIAN(C20:L20),0) -> 0.21651719
B22: Return on Capital Employed | C22: =IFERROR(('Historical FS'!C18-'Historical FS'!C24)/(SUM('Historical FS'!C49:C51)),0) -> 0.24500594 | D22: =IFERROR(('Historical FS'!D18-'Historical FS'!D24)/(SUM('Historical FS'!D49:D51)),0) -> 0.26121713 | E22: =IFERROR(('Historical FS'!E18-'Historical FS'!E24)/(SUM('Historical FS'!E49:E51)),0) -> 0.27959291 | F22: =IFERROR(('Historical FS'!F18-'Historical FS'!F24)/(SUM('Historical FS'!F49:F51)),0) -> 0.27644365 | G22: =IFERROR(('Historical FS'!G18-'Historical FS'!G24)/(SUM('Historical FS'!G49:G51)),0) -> 0.30145943 | H22: =IFERROR(('Historical FS'!H18-'Historical FS'!H24)/(SUM('Historical FS'!H49:H51)),0) -> 0.34661734 | I22: =IFERROR(('Historical FS'!I18-'Historical FS'!I24)/(SUM('Historical FS'!I49:I51)),0) -> 0.3692089 | J22: =IFERROR(('Historical FS'!J18-'Historical FS'!J24)/(SUM('Historical FS'!J49:J51)),0) -> 0.32906971 | ... L22: =IFERROR(('Historical FS'!L18-'Historical FS'!L24)/(SUM('Historical FS'!L49:L51)),0) -> 0.36635041 | N22: =IFERROR(AVERAGE(C22:L22),0) -> 0.31058223 | O22: =IFERROR(MEDIAN(C22:L22),0) -> 0.31526457
B23: Retained Earnings % | C23: =IFERROR('Historical FS'!C46,0) -> 0.58952135 | D23: =IFERROR('Historical FS'!D46,0) -> 0.40947034 | E23: =IFERROR('Historical FS'!E46,0) -> 0.40152498 | F23: =IFERROR('Historical FS'!F46,0) -> 0.55363904 | G23: =IFERROR('Historical FS'!G46,0) -> 0.4094836 | H23: =IFERROR('Historical FS'!H46,0) -> 0.41264337 | I23: =IFERROR('Historical FS'!I46,0) -> 0.41640949 | J23: =IFERROR('Historical FS'!J46,0) -> 0.2741085 | ... L23: =IFERROR('Historical FS'!L46,0) -> 0.34076135 | N23: =IFERROR(AVERAGE(C23:L23),0) -> 0.41411022 | O23: =IFERROR(MEDIAN(C23:L23),0) -> 0.40947697
B24: Return on Equity % | C24: =IFERROR('Historical FS'!C35/SUM('Historical FS'!C49:C50),0) -> 0.20806877 | D24: =IFERROR('Historical FS'!D35/SUM('Historical FS'!D49:D50),0) -> 0.24689247 | E24: =IFERROR('Historical FS'!E35/SUM('Historical FS'!E49:E50),0) -> 0.23726674 | F24: =IFERROR('Historical FS'!F35/SUM('Historical FS'!F49:F50),0) -> 0.2542246 | G24: =IFERROR('Historical FS'!G35/SUM('Historical FS'!G49:G50),0) -> 0.25439091 | H24: =IFERROR('Historical FS'!H35/SUM('Historical FS'!H49:H50),0) -> 0.29390843 | I24: =IFERROR('Historical FS'!I35/SUM('Historical FS'!I49:I50),0) -> 0.31970507 | J24: =IFERROR('Historical FS'!J35/SUM('Historical FS'!J49:J50),0) -> 0.29788007 | ... L24: =IFERROR('Historical FS'!L35/SUM('Historical FS'!L49:L50),0) -> 0.31742989 | N24: =IFERROR(AVERAGE(C24:L24),0) -> 0.2708942 | O24: =IFERROR(MEDIAN(C24:L24),0) -> 0.266783
B25: Self Sustained Growth Rate | C25: =IFERROR(C23*C24,0) -> 0.12266098 | D25: =IFERROR(D23*D24,0) -> 0.10109514 | E25: =IFERROR(E23*E24,0) -> 0.095268523 | F25: =IFERROR(F23*F24,0) -> 0.14074866 | G25: =IFERROR(G23*G24,0) -> 0.1041689 | H25: =IFERROR(H23*H24,0) -> 0.12127936 | I25: =IFERROR(I23*I24,0) -> 0.13312822 | J25: =IFERROR(J23*J24,0) -> 0.081651459 | ... L25: =IFERROR(L23*L24,0) -> 0.10816784 | N25: =IFERROR(AVERAGE(C25:L25),0) -> 0.11012852 | O25: =IFERROR(MEDIAN(C25:L25),0) -> 0.10616837
B26: Interest Coverage Ratio | C26: =IFERROR(('Historical FS'!C18-'Historical FS'!C24)/'Historical FS'!C21,0) -> 0 | D26: =IFERROR(('Historical FS'!D18-'Historical FS'!D24)/'Historical FS'!D21,0) -> 0 | E26: =IFERROR(('Historical FS'!E18-'Historical FS'!E24)/'Historical FS'!E21,0) -> 0 | F26: =IFERROR(('Historical FS'!F18-'Historical FS'!F24)/'Historical FS'!F21,0) -> 113.96471 | G26: =IFERROR(('Historical FS'!G18-'Historical FS'!G24)/'Historical FS'!G21,0) -> 126.26667 | H26: =IFERROR(('Historical FS'!H18-'Historical FS'!H24)/'Historical FS'!H21,0) -> 140.075 | I26: =IFERROR(('Historical FS'!I18-'Historical FS'!I24)/'Historical FS'!I21,0) -> 108.82042 | J26: =IFERROR(('Historical FS'!J18-'Historical FS'!J24)/'Historical FS'!J21,0) -> 67.546809 | ... L26: =IFERROR(('Historical FS'!L18-'Historical FS'!L24)/'Historical FS'!L21,0) -> 89.850962 | N26: =IFERROR(AVERAGE(C26:L26),0) -> 72.927457 | O26: =IFERROR(MEDIAN(C26:L26),0) -> 86.300481
B28: Debtor Turnover Ratio | C28: =IFERROR('Historical FS'!C6/'Historical FS'!C61,0) -> 5.557864 | D28: =IFERROR('Historical FS'!D6/'Historical FS'!D61,0) -> 5.3661543 | E28: =IFERROR('Historical FS'!E6/'Historical FS'!E61,0) -> 5.5759763 | F28: =IFERROR('Historical FS'!F6/'Historical FS'!F61,0) -> 4.9110726 | G28: =IFERROR('Historical FS'!G6/'Historical FS'!G61,0) -> 5.207422 | H28: =IFERROR('Historical FS'!H6/'Historical FS'!H61,0) -> 5.3591065 | I28: =IFERROR('Historical FS'!I6/'Historical FS'!I61,0) -> 5.7727738 | J28: =IFERROR('Historical FS'!J6/'Historical FS'!J61,0) -> 5.0895903 | ... L28: =IFERROR('Historical FS'!L6/'Historical FS'!L61,0) -> 5.0703866 | N28: =IFERROR(AVERAGE(C28:L28),0) -> 5.3141427 | O28: =IFERROR(MEDIAN(C28:L28),0) -> 5.2950934
B29: Creditor Turnover Ratio | C29: =IFERROR('Historical FS'!C6/'Historical FS'!C52,0) -> 4.8343922 | D29: =IFERROR('Historical FS'!D6/'Historical FS'!D52,0) -> 4.8885346 | E29: =IFERROR('Historical FS'!E6/'Historical FS'!E52,0) -> 4.3244586 | F29: =IFERROR('Historical FS'!F6/'Historical FS'!F52,0) -> 4.1806419 | G29: =IFERROR('Historical FS'!G6/'Historical FS'!G52,0) -> 3.8889878 | H29: =IFERROR('Historical FS'!H6/'Historical FS'!H52,0) -> 3.3878568 | I29: =IFERROR('Historical FS'!I6/'Historical FS'!I52,0) -> 3.5893128 | J29: =IFERROR('Historical FS'!J6/'Historical FS'!J52,0) -> 3.8859527 | ... L29: =IFERROR('Historical FS'!L6/'Historical FS'!L52,0) -> 3.4184845 | N29: =IFERROR(AVERAGE(C29:L29),0) -> 4.0124108 | O29: =IFERROR(MEDIAN(C29:L29),0) -> 3.8874703
B30: Inventory Turnover Ratio | C30: =IFERROR('Historical FS'!C6/'Historical FS'!C62,0) -> 0 | D30: =IFERROR('Historical FS'!D6/'Historical FS'!D62,0) -> 0 | E30: =IFERROR('Historical FS'!E6/'Historical FS'!E62,0) -> 0 | F30: =IFERROR('Historical FS'!F6/'Historical FS'!F62,0) -> 0 | G30: =IFERROR('Historical FS'!G6/'Historical FS'!G62,0) -> 0 | H30: =IFERROR('Historical FS'!H6/'Historical FS'!H62,0) -> 0 | I30: =IFERROR('Historical FS'!I6/'Historical FS'!I62,0) -> 0 | J30: =IFERROR('Historical FS'!J6/'Historical FS'!J62,0) -> 0 | ... L30: =IFERROR('Historical FS'!L6/'Historical FS'!L62,0) -> 0 | N30: =IFERROR(AVERAGE(C30:L30),0) -> 0 | O30: =IFERROR(MEDIAN(C30:L30),0) -> 0
